Workbook
Name kurs: 'February''26'!#REF!
Name kurs: 'JANUARY''26'!#REF!
Name kurs: '[1]07'!$H$6

Sheet JANUARY'26
B5: INVOICE PERIOD
A6: Start | B6: 46023
A7: End | B7: 46053
B8: INBOUND | D8: OUTBOUND | F8: STORAGE BOX | G8: Daily Storage Cost
B9: Invoice Numbers | C9: No of boxes | D9: Order No | E9: No of boxes
A10: Day in month | B10: Starting Stock | F10: 13599
A11: 46023 | B11: Нач. ост. | C11: 13354 | F11: =F10 -> 13599 | G11: =F11*$F$53 -> 421569
A12: 46024 | B12: Без номера | C12: 1187 | F12: =F11+C12-E12 -> 14786 | G12: =F12*$F$53 -> 458366
A13: 46025 | B13: IHR778 | C13: 1337 | F13: =F12+C13-E13 -> 16123 | G13: =F13*$F$53 -> 499813
A14: 46026 | B14: IHR776 | C14: 1609 | F14: =F13+C14-E14 -> 17732 | G14: =F14*$F$53 -> 549692
A15: 46027 | B15: IHR783 | C15: 1308 | F15: =F14+C15-E15 -> 19040 | G15: =F15*$F$53 -> 590240
A16: 46028 | B16: ANT283 | C16: 1114 | F16: =F15+C16-E16 -> 20154 | G16: =F16*$F$53 -> 624774
A17: 46029 | B17: ANT277 | C17: 65 | F17: =F16+C17-E17 -> 20219 | G17: =F17*$F$53 -> 626789
A18: 46030 | B18: IHR805 | C18: 1568 | F18: =F17+C18-E18 -> 21787 | G18: =F18*$F$53 -> 675397
A19: 46031 | B19: IHR803 | C19: 1022 | E19: =VLOOKUP(A19,[2]Çıkış!$A:$H,8,FALSE) -> 1441 | F19: =F18+C19-E19 -> 21368 | G19: =F19*$F$53 -> 662408
A20: 46032 | B20: IHR821 | C20: 943 | F20: =F19+C20-E20 -> 22311 | G20: =F20*$F$53 -> 691641
A21: 46033 | B21: ANT298 | C21: 134 | F21: =F20+C21-E21 -> 22445 | G21: =F21*$F$53 -> 695795
A22: 46034 | B22: ANT307 | C22: 1131 | E22: =VLOOKUP(A22,[2]Çıkış!$A:$H,8,FALSE) -> 964 | F22: =F21+C22-E22 -> 22612 | G22: =F22*$F$53 -> 700972
A23: 46035 | B23: IHR845 | C23: 490 | E23: =VLOOKUP(A23,[2]Çıkış!$A:$H,8,FALSE) -> 205 | F23: =F22+C23-E23 -> 22897 | G23: =F23*$F$53 -> 709807
A24: 46036 | B24: ANT309 | C24: 724 | F24: =F23+C24-E24 -> 23621 | G24: =F24*$F$53 -> 732251
A25: 46037 | B25: IHR844 | C25: 1285 | F25: =F24+C25-E25 -> 24906 | G25: =F25*$F$53 -> 772086
A26: 46038 | B26: IHR865 | C26: 1058 | E26: =VLOOKUP(A26,[2]Çıkış!$A:$H,8,FALSE) -> 381 | F26: =F25+C26-E26 -> 25583 | G26: =F26*$F$53 -> 793073
A27: 46039 | F27: =F26+C27-E27 -> 25583 | G27: =F27*$F$53 -> 793073
A28: 46040 | F28: =F27+C28-E28 -> 25583 | G28: =F28*$F$53 -> 793073
A29: 46041 | E29: =VLOOKUP(A29,[2]Çıkış!$A:$H,8,FALSE) -> 690 | F29: =F28+C29-E29 -> 24893 | G29: =F29*$F$53 -> 771683
A30: 46042 | E30: =VLOOKUP(A30,[2]Çıkış!$A:$H,8,FALSE) -> 894 | F30: =F29+C30-E30 -> 23999 | G30: =F30*$F$53 -> 743969
A31: 46043 | E31: =VLOOKUP(A31,[2]Çıkış!$A:$H,8,FALSE) -> 1103 | F31: =F30+C31-E31 -> 22896 | G31: =F31*$F$53 -> 709776
A32: 46044 | E32: =VLOOKUP(A32,[2]Çıkış!$A:$H,8,FALSE) -> 1163 | F32: =F31+C32-E32 -> 21733 | G32: =F32*$F$53 -> 673723
A33: 46045 | E33: =VLOOKUP(A33,[2]Çıkış!$A:$H,8,FALSE) -> 1487 | F33: =F32+C33-E33 -> 20246 | G33: =F33*$F$53 -> 627626
A34: 46046 | F34: =F33+C34-E34 -> 20246 | G34: =F34*$F$53 -> 627626
A35: 46047 | F35: =F34+C35-E35 -> 20246 | G35: =F35*$F$53 -> 627626
A36: 46048 | E36: =VLOOKUP(A36,[2]Çıkış!$A:$H,8,FALSE) -> 277 | F36: =F35+C36-E36 -> 19969 | G36: =F36*$F$53 -> 619039
A37: 46049 | F37: =F36+C37-E37 -> 19969 | G37: =F37*$F$53 -> 619039
A38: 46050 | E38: =VLOOKUP(A38,[2]Çıkış!$A:$H,8,FALSE) -> 893 | F38: =F37+C38-E38 -> 19076 | G38: =F38*$F$53 -> 591356
A39: 46051 | E39: =VLOOKUP(A39,[2]Çıkış!$A:$H,8,FALSE) -> 1815 | F39: =F38+C39-E39 -> 17261 | G39: =F39*$F$53 -> 535091
A40: 46052 | E40: =VLOOKUP(A40,[2]Çıkış!$A:$H,8,FALSE) -> 608 | F40: =F39+C40-E40 -> 16653 | G40: =F40*$F$53 -> 516243
A41: 46053
B42: TOTAL | C42: =SUM(C11:C41) -> 28329 | E42: =SUM(E10:E41) -> 11921 | F42: =SUM(F11:F41) -> 627536 | G42: =SUM(G11:G41) -> 19453616
B45: INBOUND AMOUNT | C45: =C42*F51 -> 3116190 | D45: OUTBOUND AMOUNT | E45: =E42*F52 -> 1311310
B47: TOTAL AMOUNT (Excluding VAT) | C47: =C45+E45 -> 4427500
...

Sheet February'26
B5: INVOICE PERIOD
A6: Start | B6: 46054
A7: End | B7: 46081
B8: INBOUND | D8: OUTBOUND | F8: STORAGE BOX | G8: Daily Storage Cost
B9: Invoice Numbers | C9: No of boxes | D9: Order No | E9: No of boxes
A10: Day in month | B10: Starting Stock | F10: 16653
A11: 46054 | F11: =F10 -> 16653 | G11: =F11*$F$53 -> 516243
A12: 46055 | B12: Mağaza Malzemeleri ve Mobilyaları | C12: 565 | F12: =F11+C12-E12 -> 17218 | G12: =F12*$F$53 -> 533758
A13: 46056 | C13: 1381 | F13: =F12+C13-E13 -> 18599 | G13: =F13*$F$53 -> 576569
A14: 46057 | C14: 1225 | E14: 443 | F14: =F13+C14-E14 -> 19381 | G14: =F14*$F$53 -> 600811
A15: 46058 | E15: 1316 | F15: =F14+C15-E15 -> 18065 | G15: =F15*$F$53 -> 560015
A16: 46059 | E16: 1149 | F16: =F15+C16-E16 -> 16916 | G16: =F16*$F$53 -> 524396
A17: 46060 | F17: =F16+C17-E17 -> 16916 | G17: =F17*$F$53 -> 524396
A18: 46061 | F18: =F17+C18-E18 -> 16916 | G18: =F18*$F$53 -> 524396
A19: 46062 | F19: =F18+C19-E19 -> 16916 | G19: =F19*$F$53 -> 524396
A20: 46063 | C20: 1168 | F20: =F19+C20-E20 -> 18084 | G20: =F20*$F$53 -> 560604
A21: 46064 | E21: 744 | F21: =F20+C21-E21 -> 17340 | G21: =F21*$F$53 -> 537540
A22: 46065 | E22: 608 | F22: =F21+C22-E22 -> 16732 | G22: =F22*$F$53 -> 518692
A23: 46066 | F23: =F22+C23-E23 -> 16732 | G23: =F23*$F$53 -> 518692
A24: 46067 | F24: =F23+C24-E24 -> 16732 | G24: =F24*$F$53 -> 518692
A25: 46068 | F25: =F24+C25-E25 -> 16732 | G25: =F25*$F$53 -> 518692
A26: 46069 | E26: 470 | F26: =F25+C26-E26 -> 16262 | G26: =F26*$F$53 -> 504122
A27: 46070 | E27: 480 | F27: =F26+C27-E27 -> 15782 | G27: =F27*$F$53 -> 489242
A28: 46071 | F28: =F27+C28-E28 -> 15782 | G28: =F28*$F$53 -> 489242
A29: 46072 | C29: 1999 | E29: 642 | F29: =F28+C29-E29 -> 17139 | G29: =F29*$F$53 -> 531309
A30: 46073 | E30: 474 | F30: =F29+C30-E30 -> 16665 | G30: =F30*$F$53 -> 516615
A31: 46074 | F31: =F30+C31-E31 -> 16665 | G31: =F31*$F$53 -> 516615
A32: 46075 | F32: =F31+C32-E32 -> 16665 | G32: =F32*$F$53 -> 516615
A33: 46076 | F33: =F32+C33-E33 -> 16665 | G33: =F33*$F$53 -> 516615
A34: 46077 | F34: =F33+C34-E34 -> 16665 | G34: =F34*$F$53 -> 516615
A35: 46078 | F35: =F34+C35-E35 -> 16665 | G35: =F35*$F$53 -> 516615
A36: 46079 | F36: =F35+C36-E36 -> 16665 | G36: =F36*$F$53 -> 516615
A37: 46080 | F37: =F36+C37-E37 -> 16665 | G37: =F37*$F$53 -> 516615
A38: 46081 | F38: =F37+C38-E38 -> 16665 | G38: =F38*$F$53 -> 516615
G39: =F39*$F$53 -> 0
G40: =F40*$F$53 -> 0
B42: TOTAL | C42: =SUM(C11:C41) -> 6338 | E42: =SUM(E10:E41) -> 6326 | F42: =SUM(F11:F41) -> 474882 | G42: =SUM(G11:G41) -> 14721342
B45: INBOUND AMOUNT | C45: =C42*F51 -> 697180 | D45: OUTBOUND AMOUNT | E45: =E42*F52 -> 695860
B47: TOTAL AMOUNT (Excluding VAT) | C47: =C45+E45 -> 1393040
E50: QTTY | F50: UNIT PRICE | G50: AMOUNT
...
